ERROR - ‚ùå Error processing depth 0: 'CallToolResult' object has no attribute 'get'
Traceback (most recent call last):
  File "/app/app/services/dbt_analysis_service.py", line 540, in analyze_dbt_file_for_iterative_query
    if isinstance(column_metadata_result.get("content"), list):
                  ^^^^^^^^^^^^^^^^^^^^^^^^^^
  File "/usr/local/lib/python3.13/site-packages/pydantic/main.py", line 991, in __getattr__
    raise AttributeError(f'{type(self).__name__!r} object has no attribute {item!r}')
AttributeError: 'CallToolResult' object has no attribute 'get'
